<?xml version="1.0" encoding="UTF-8"?>
<testng-results retried="1" ignored="0" total="2" passed="1" failed="0" skipped="0">
  <reporter-output>
  </reporter-output>
  <suite started-at="2025-06-16T23:25:03 IST" name="Suite" finished-at="2025-06-16T23:25:03 IST" duration-ms="65">
    <groups>
    </groups>
    <test started-at="2025-06-16T23:25:03 IST" name="Retry Test" finished-at="2025-06-16T23:25:03 IST" duration-ms="65">
      <class name="Santhiya.Tests.RetryAnalyzerTest">
        <test-method retried="true" signature="retryTestExample()[pri:0, instance:Santhiya.Tests.RetryAnalyzerTest@71d44a3]" started-at="2025-06-16T23:25:03 IST" name="retryTestExample" finished-at="2025-06-16T23:25:03 IST" duration-ms="21" status="SKIP">
          <exception class="java.lang.AssertionError">
            <message>
              <![CDATA[Failed first attempt expected [true] but found [false]]]>
            </message>
            <full-stacktrace>
              <![CDATA[java.lang.AssertionError: Failed first attempt expected [true] but found [false]
at org.testng.Assert.fail(Assert.java:111)
at org.testng.Assert.failNotEquals(Assert.java:1590)
at org.testng.Assert.assertTrue(Assert.java:57)
at Santhiya.Tests.RetryAnalyzerTest.retryTestExample(RetryAnalyzerTest.java:17)
at java.base/jdk.internal.reflect.DirectMethodHandleAccessor.invoke(DirectMethodHandleAccessor.java:103)
at java.base/java.lang.reflect.Method.invoke(Method.java:580)
at org.testng.internal.invokers.MethodInvocationHelper.invokeMethod(MethodInvocationHelper.java:141)
at org.testng.internal.invokers.TestInvoker.invokeMethod(TestInvoker.java:687)
at org.testng.internal.invokers.TestInvoker.invokeTestMethod(TestInvoker.java:230)
at org.testng.internal.invokers.MethodRunner.runInSequence(MethodRunner.java:63)
at org.testng.internal.invokers.TestInvoker$MethodInvocationAgent.invoke(TestInvoker.java:995)
at org.testng.internal.invokers.TestInvoker.invokeTestMethods(TestInvoker.java:203)
at org.testng.internal.invokers.TestMethodWorker.invokeTestMethods(TestMethodWorker.java:154)
at org.testng.internal.invokers.TestMethodWorker.run(TestMethodWorker.java:134)
at java.base/java.util.ArrayList.forEach(ArrayList.java:1596)
at org.testng.TestRunner.privateRun(TestRunner.java:741)
at org.testng.TestRunner.run(TestRunner.java:616)
at org.testng.SuiteRunner.runTest(SuiteRunner.java:421)
at org.testng.SuiteRunner$SuiteWorker.run(SuiteRunner.java:463)
at org.testng.internal.thread.ThreadUtil.lambda$execute$0(ThreadUtil.java:64)
at java.base/java.util.concurrent.FutureTask.run(FutureTask.java:317)
at java.base/java.util.concurrent.ThreadPoolExecutor.runWorker(ThreadPoolExecutor.java:1144)
at java.base/java.util.concurrent.ThreadPoolExecutor$Worker.run(ThreadPoolExecutor.java:642)
at java.base/java.lang.Thread.run(Thread.java:1583)
]]>
            </full-stacktrace>
          </exception> <!-- java.lang.AssertionError -->
          <reporter-output>
          </reporter-output>
        </test-method> <!-- retryTestExample -->
        <test-method signature="retryTestExample()[pri:0, instance:Santhiya.Tests.RetryAnalyzerTest@71d44a3]" started-at="2025-06-16T23:25:03 IST" name="retryTestExample" finished-at="2025-06-16T23:25:03 IST" duration-ms="2" status="PASS">
          <reporter-output>
          </reporter-output>
        </test-method> <!-- retryTestExample -->
      </class> <!-- Santhiya.Tests.RetryAnalyzerTest -->
    </test> <!-- Retry Test -->
  </suite> <!-- Suite -->
</testng-results>
